<?xml version='1.0' encoding='utf-8'?>
<robot name="rx1" version="1.0">
  <link name="world" />
  <joint name="world_joint" type="fixed">
    <origin rpy="0.0 0.0 0.0" xyz="0 0 0.621251" />
    <parent link="world" />
    <child link="base_link" />
  </joint>
  <material name="red">
    <color rgba="1.0 0.0 0.0 1.0" />
  </material>
  <material name="white">
    <color rgba="1.0 1.0 1.0 1.0" />
  </material>
  <material name="blue">
    <color rgba="0.0 0.0 1.0 1.0" />
  </material>
  <material name="yellow">
    <color rgba="1.0 1.0 0.0 1.0" />
  </material>
  <material name="black">
    <color rgba="0.1 0.1 0.1 1.0" />
  </material>
  <link name="base_link">
    <inertial>
      <mass value="7.0" />
      <inertia ixx="0.1479926256185778" ixy="0.0" ixz="0.0" iyy="0.1480031283986734" iyz="0.0" izz="0.013240506334916875" />
    </inertial>
  </link>
  <link name="torso_pitch_link">
    <inertial>
      <mass value="0.5" />
      <inertia ixx="6.5625e-05" ixy="0.0" ixz="0.0" iyy="6.5625e-05" iyz="0.0" izz="5.625e-05" />
    </inertial>
    <collision>
      <origin rpy="1.57075 0.0 0.0" xyz="0.0 0.0 0.0" />
      <geometry>
        <cylinder length="0.03" radius="0.01" />
      </geometry>
    </collision>
  </link>
  <joint name="torso_yaw2pitch_joint" type="fixed">
    <origin rpy="0.0 0.0 0.0" xyz="0.03 0.0 -0.1775" />
    <parent link="lift_platform_link" />
    <child link="torso_pitch_link" />
  </joint>
  <link name="torso_roll_link">
    <inertial>
      <mass value="0.5" />
      <inertia ixx="6.5625e-05" ixy="0.0" ixz="0.0" iyy="6.5625e-05" iyz="0.0" izz="5.625e-05" />
    </inertial>
    <collision>
      <origin rpy="0.0 1.57075 0.0" xyz="0.0 0.0 0.0" />
      <geometry>
        <cylinder length="0.03" radius="0.01" />
      </geometry>
    </collision>
  </link>
  <joint name="torso_pitch2roll_joint" type="fixed">
    <origin rpy="0.0 0.0 0.0" xyz="0.0 0.0 0.0" />
    <parent link="torso_pitch_link" />
    <child link="torso_roll_link" />
    <dynamics damping="0.5" friction="0.1" />
  </joint>
  <link name="torso_link">
    <inertial>
      <mass value="1.0" />
      <inertia ixx="0.00839643176338393" ixy="0.0" ixz="0.0" iyy="0.003718667304595339" iyz="0.0" izz="0.005448431209219654" />
    </inertial>
    <visual>
      <origin rpy="0.0 0.0 0.0" xyz="0.0 0.0 0.0" />
      <geometry>
        <mesh filename="package://RRR_Cater/RX1/rx1_description/meshes/torso_link.stl" />
      </geometry>
      <material name="white" />
    </visual>
    <collision>
      <origin rpy="0.0 0.0 0.0" xyz="0.0 0.0 0.0" />
      <geometry>
        <mesh filename="package://RRR_Cater/RX1/rx1_description/meshes/torso_link.stl" />
      </geometry>
    </collision>
  </link>
  <joint name="torso_roll2torso_joint" type="fixed">
    <origin rpy="0.0 0.0 0.0" xyz="0.0 0.0 0.08" />
    <parent link="torso_roll_link" />
    <child link="torso_link" />
  </joint>
  <link name="head_base_link">
    <inertial>
      <mass value="0.05" />
      <inertia ixx="3.4733338386813986e-05" ixy="0.0" ixz="0.0" iyy="2.3066669137279266e-05" iyz="0.0" izz="4.1666671633720553e-05" />
    </inertial>
    <visual>
      <origin rpy="0.0 0.0 0.0" xyz="0.0 0.0 0.0" />
      <geometry>
        <mesh filename="package://RRR_Cater/RX1/rx1_description/meshes/head/head_base_link.stl" />
      </geometry>
      <material name="white" />
    </visual>
    <collision>
      <origin rpy="0.0 0.0 0.0" xyz="0.0 0.0 0.0" />
      <geometry>
        <mesh filename="package://RRR_Cater/RX1/rx1_description/meshes/head/head_base_link.stl" />
      </geometry>
    </collision>
  </link>
  <joint name="torso2head_base_joint" type="fixed">
    <origin rpy="0.0 0.0 0.0" xyz="0.0 0.0 0.21" />
    <parent link="torso_link" />
    <child link="head_base_link" />
  </joint>
  <link name="neck_yaw_link">
    <inertial>
      <mass value="0.05" />
      <inertia ixx="2.6332792163843353e-05" ixy="0.0" ixz="0.0" iyy="3.551715988694438e-05" iyz="0.0" izz="2.3884367326730143e-05" />
    </inertial>
    <visual>
      <origin rpy="0.0 0.0 0.0" xyz="0.0 0.0 0.0" />
      <geometry>
        <mesh filename="package://RRR_Cater/RX1/rx1_description/meshes/head/neck_yaw_link.stl" />
      </geometry>
      <material name="white" />
    </visual>
    <collision>
      <origin rpy="0.0 0.0 0.0" xyz="0.0 0.0 0.0" />
      <geometry>
        <mesh filename="package://RRR_Cater/RX1/rx1_description/meshes/head/neck_yaw_link.stl" />
      </geometry>
    </collision>
  </link>
  <joint name="head_base2neck_yaw_joint" type="fixed">
    <origin rpy="0.0 0.0 0.0" xyz="0.0 0.0 0.0" />
    <parent link="head_base_link" />
    <child link="neck_yaw_link" />
  </joint>
  <link name="neck_pitch_link">
    <inertial>
      <mass value="0.05" />
      <inertia ixx="9.366899537678521e-05" ixy="0.0" ixz="0.0" iyy="9.765486239335953e-05" iyz="0.0" izz="2.9194203491569232e-05" />
    </inertial>
    <visual>
      <origin rpy="0.0 0.0 0.0" xyz="0.0 0.0 0.0" />
      <geometry>
        <mesh filename="package://RRR_Cater/RX1/rx1_description/meshes/head/neck_pitch_link.stl" />
      </geometry>
      <material name="white" />
    </visual>
    <collision>
      <origin rpy="0.0 0.0 0.0" xyz="0.0 0.0 0.0" />
      <geometry>
        <mesh filename="package://RRR_Cater/RX1/rx1_description/meshes/head/neck_pitch_link.stl" />
      </geometry>
    </collision>
  </link>
  <joint name="neck_yaw2pitch_joint" type="fixed">
    <origin rpy="0.0 0.0 0.0" xyz="0.0 0.0 0.035" />
    <parent link="neck_yaw_link" />
    <child link="neck_pitch_link" />
  </joint>
  <link name="head_depth_cam_mount_link">
    <inertial>
      <mass value="0.05" />
      <inertia ixx="0.00011445736975046934" ixy="0.0" ixz="0.0" iyy="4.306387919284874e-05" iyz="0.0" izz="0.00011610652434354089" />
    </inertial>
    <visual>
      <origin rpy="0.0 0.0 0.0" xyz="0.0 0.0 0.0" />
      <geometry>
        <mesh filename="package://RRR_Cater/RX1/rx1_description/meshes/head/head_depth_cam_mount_link.stl" />
      </geometry>
      <material name="white" />
    </visual>
    <collision>
      <origin rpy="0.0 0.0 0.0" xyz="0.0 0.0 0.0" />
      <geometry>
        <mesh filename="package://RRR_Cater/RX1/rx1_description/meshes/head/head_depth_cam_mount_link.stl" />
      </geometry>
    </collision>
  </link>
  <joint name="neck_pitch2head_depth_cam_mount_joint" type="fixed">
    <origin rpy="0.0 0.0 0.0" xyz="-0.01 0.0 0.1" />
    <parent link="neck_pitch_link" />
    <child link="head_depth_cam_mount_link" />
  </joint>
  <link name="camera_link">
    <inertial>
      <mass value="0.05" />
      <inertia ixx="8.333333333333333e-07" ixy="0.0" ixz="0.0" iyy="8.333333333333333e-07" iyz="0.0" izz="8.333333333333333e-07" />
    </inertial>
    <visual>
      <origin rpy="0.0 0.0 0.0" xyz="0.0 0.0 0.0" />
      <geometry>
        <box size="0.01 0.01 0.01" />
      </geometry>
      <material name="white" />
    </visual>
    <collision>
      <origin rpy="0.0 0.0 0.0" xyz="0.0 0.0 0.0" />
      <geometry>
        <box size="0.01 0.01 0.01" />
      </geometry>
    </collision>
  </link>
  <joint name="head_depth_cam_mount2camera_joint" type="fixed">
    <origin rpy="0.0 0.0 0.0" xyz="0.05 0.0 0.03" />
    <parent link="head_depth_cam_mount_link" />
    <child link="camera_link" />
  </joint>
  <link name="right_ear_link">
    <inertial>
      <mass value="0.05" />
      <inertia ixx="7.075414581789501e-05" ixy="0.0" ixz="0.0" iyy="7.708227986119268e-05" iyz="0.0" izz="7.00313496307216e-06" />
    </inertial>
    <visual>
      <origin rpy="0.0 0.0 0.0" xyz="0.0 0.0 0.0" />
      <geometry>
        <mesh filename="package://RRR_Cater/RX1/rx1_description/meshes/head/right_ear_link.stl" />
      </geometry>
      <material name="white" />
    </visual>
    <collision>
      <origin rpy="0.0 0.0 0.0" xyz="0.0 0.0 0.0" />
      <geometry>
        <mesh filename="package://RRR_Cater/RX1/rx1_description/meshes/head/right_ear_link.stl" />
      </geometry>
    </collision>
  </link>
  <joint name="head_depth_cam_mount2right_ear_joint" type="fixed">
    <origin rpy="0.0 0.0 0.0" xyz="0.0 -0.065 0.045" />
    <parent link="head_depth_cam_mount_link" />
    <child link="right_ear_link" />
  </joint>
  <link name="left_ear_link">
    <inertial>
      <mass value="0.05" />
      <inertia ixx="7.075414588774426e-05" ixy="0.0" ixz="0.0" iyy="7.708227861952545e-05" iyz="0.0" izz="7.003133791254161e-06" />
    </inertial>
    <visual>
      <origin rpy="0.0 0.0 0.0" xyz="0.0 0.0 0.0" />
      <geometry>
        <mesh filename="package://RRR_Cater/RX1/rx1_description/meshes/head/left_ear_link.stl" />
      </geometry>
      <material name="white" />
    </visual>
    <collision>
      <origin rpy="0.0 0.0 0.0" xyz="0.0 0.0 0.0" />
      <geometry>
        <mesh filename="package://RRR_Cater/RX1/rx1_description/meshes/head/left_ear_link.stl" />
      </geometry>
    </collision>
  </link>
  <joint name="head_depth_cam_mount2left_ear_joint" type="fixed">
    <origin rpy="0.0 0.0 0.0" xyz="0.0 0.065 0.045" />
    <parent link="head_depth_cam_mount_link" />
    <child link="left_ear_link" />
  </joint>
  <link name="right_shoul_base_link">
    <inertial>
      <mass value="0.2" />
      <inertia ixx="0.00011374999999999999" ixy="0.0" ixz="0.0" iyy="0.00011374999999999999" iyz="0.0" izz="4e-05" />
    </inertial>
    <visual>
      <origin rpy="0.0 0.0 0.0" xyz="0.0 0.0 0.0375" />
      <geometry>
        <cylinder length="0.075" radius="0.02" />
      </geometry>
      <material name="white" />
    </visual>
    <collision>
      <origin rpy="0.0 0.0 0.0" xyz="0.0 0.0 0.0375" />
      <geometry>
        <cylinder length="0.075" radius="0.02" />
      </geometry>
    </collision>
  </link>
  <joint name="head_base2right_shoul_base_joint" type="fixed">
    <origin rpy="1.04706195 0.0 0.0" xyz="0.0 -0.12 -0.05" />
    <parent link="head_base_link" />
    <child link="right_shoul_base_link" />
  </joint>
  <link name="right_shoul_link">
    <inertial>
      <mass value="0.2" />
      <inertia ixx="0.00015166666666666668" ixy="0.0" ixz="0.0" iyy="0.00015166666666666668" iyz="0.0" izz="9e-05" />
    </inertial>
    <visual>
      <origin rpy="0.0 0.0 0.0" xyz="0.0 0.0 0.04" />
      <geometry>
        <cylinder length="0.08" radius="0.03" />
      </geometry>
      <material name="red" />
    </visual>
    <collision>
      <origin rpy="0.0 0.0 0.0" xyz="0.0 0.0 0.04" />
      <geometry>
        <cylinder length="0.08" radius="0.03" />
      </geometry>
    </collision>
  </link>
  <joint name="right_shoul_base2shoul_joint[11]" type="revolute">
    <origin rpy="0.0 0.0 0.0" xyz="0.0 0.0 0.075" />
    <axis xyz="0.0 0.0 -1.0" />
    <parent link="right_shoul_base_link" />
    <child link="right_shoul_link" />
    <limit effort="50.0" lower="-1.483355" upper="0.578286" velocity="15.0" />
    <dynamics damping="0.5" friction="0.1" />
  </joint>
  <link name="right_shoul_rot_link">
    <inertial>
      <mass value="0.2" />
      <inertia ixx="7.166666666666667e-05" ixy="0.0" ixz="0.0" iyy="7.166666666666667e-05" iyz="0.0" izz="9e-05" />
    </inertial>
    <visual>
      <origin rpy="0.0 1.57075 0.0" xyz="0.0 0.0 0.0" />
      <geometry>
        <cylinder length="0.04" radius="0.03" />
      </geometry>
      <material name="blue" />
    </visual>
    <collision>
      <origin rpy="0.0 1.57075 0.0" xyz="0.0 0.0 0.0" />
      <geometry>
        <cylinder length="0.04" radius="0.03" />
      </geometry>
    </collision>
  </link>
  <joint name="right_shoul2shoul_rot_joint[12]" type="revolute">
    <origin rpy="-1.04706195 0.0 0.0" xyz="0.0 0.0 0.08" />
    <axis xyz="-1.0 0.0 0.0" />
    <parent link="right_shoul_link" />
    <child link="right_shoul_rot_link" />
    <limit effort="50.0" lower="-0.047066" upper="1.997238" velocity="15.0" />
    <dynamics damping="0.5" friction="0.1" />
  </joint>
  <link name="right_upper_arm_link">
    <inertial>
      <mass value="0.1" />
      <inertia ixx="0.00026469309370525756" ixy="0.0" ixz="0.0" iyy="0.000295128481794064" iyz="0.0" izz="9.863136459929792e-05" />
    </inertial>
    <visual>
      <origin rpy="0.0 0.0 0.0" xyz="0.0 0.0 0.0" />
      <geometry>
        <mesh filename="package://RRR_Cater/RX1/rx1_description/meshes/right_arm/right_upper_arm_link.stl" />
      </geometry>
      <material name="white" />
    </visual>
    <collision>
      <origin rpy="0.0 0.0 0.0" xyz="0.0 0.0 0.0" />
      <geometry>
        <mesh filename="package://RRR_Cater/RX1/rx1_description/meshes/right_arm/right_upper_arm_link.stl" />
      </geometry>
    </collision>
  </link>
  <joint name="right_shoul_rot2upper_arm_joint" type="fixed">
    <origin rpy="0.0 0.0 0.0" xyz="0.0 0.0 -0.0625" />
    <parent link="right_shoul_rot_link" />
    <child link="right_upper_arm_link" />
  </joint>
  <link name="right_armrot_link">
    <inertial>
      <mass value="0.1" />
      <inertia ixx="0.000573437191095085" ixy="0.0" ixz="0.0" iyy="0.0005528666733185454" iyz="0.0" izz="8.463719774696362e-05" />
    </inertial>
    <visual>
      <origin rpy="0.0 0.0 0.0" xyz="0.0 0.0 -0.11" />
      <geometry>
        <mesh filename="package://RRR_Cater/RX1/rx1_description/meshes/right_arm/right_elbow_link.stl" />
      </geometry>
      <material name="white" />
    </visual>
    <collision>
      <origin rpy="0.0 0.0 0.0" xyz="0.0 0.0 -0.11" />
      <geometry>
        <cylinder length="0.22" radius="0.03" />
      </geometry>
    </collision>
  </link>
  <joint name="right_arm2armrot_joint[13]" type="revolute">
    <origin rpy="0.0 0.0 0.0" xyz="0.0 0.0 -0.0625" />
    <axis xyz="0.0 0.0 1.0" />
    <parent link="right_upper_arm_link" />
    <child link="right_armrot_link" />
    <limit effort="50.0" lower="-2.094395" upper="2.094395" velocity="15.0" />
    <dynamics damping="0.1" friction="0.1" />
  </joint>
  <link name="right_elbow_link">
    <inertial>
      <mass value="0.1" />
      <inertia ixx="7.583333333333334e-05" ixy="0.0" ixz="0.0" iyy="7.583333333333334e-05" iyz="0.0" izz="4.5e-05" />
    </inertial>
    <visual>
      <origin rpy="0.0 1.57075 -1.57075" xyz="0.0 0.0 0.0" />
      <geometry>
        <cylinder length="0.08" radius="0.03" />
      </geometry>
      <material name="blue" />
    </visual>
    <collision>
      <origin rpy="0.0 1.57075 -1.57075" xyz="0.0 0.0 0.0" />
      <geometry>
        <cylinder length="0.08" radius="0.03" />
      </geometry>
    </collision>
  </link>
  <joint name="right_armrot2elbow_joint[14]" type="revolute">
    <origin rpy="0.0 0.0 0.0" xyz="0.0 0.0 -0.22" />
    <axis xyz="0.0 1.0 0.0" />
    <parent link="right_armrot_link" />
    <child link="right_elbow_link" />
    <limit effort="50.0" lower="-2.094395" upper="0.0" velocity="15.0" />
    <dynamics damping="0.1" friction="0.1" />
  </joint>
  <link name="right_forearm_link">
    <inertial>
      <mass value="0.1" />
      <inertia ixx="9e-05" ixy="0.0" ixz="0.0" iyy="9e-05" iyz="0.0" izz="4.5e-05" />
    </inertial>
    <visual>
      <origin rpy="0.0 0.0 0.0" xyz="0.0 0.0 0.0" />
      <geometry>
        <cylinder length="0.09" radius="0.03" />
      </geometry>
      <material name="white" />
    </visual>
    <collision>
      <origin rpy="0.0 0.0 0.0" xyz="0.0 0.0 0.0" />
      <geometry>
        <cylinder length="0.09" radius="0.03" />
      </geometry>
    </collision>
  </link>
  <joint name="right_elbow2forearm_joint" type="fixed">
    <origin rpy="0.0 0.0 0.0" xyz="0.0 0.0 -0.045" />
    <parent link="right_elbow_link" />
    <child link="right_forearm_link" />
  </joint>
  <link name="right_forearmrot_link">
    <inertial>
      <mass value="0.1" />
      <inertia ixx="0.00038840639708807395" ixy="0.0" ixz="0.0" iyy="0.00039995180679971244" iyz="0.0" izz="0.00011242609109381833" />
    </inertial>
    <visual>
      <origin rpy="0.0 0.0 0.0" xyz="0.0 0.0 -0.09" />
      <geometry>
        <mesh filename="package://RRR_Cater/RX1/rx1_description/meshes/right_arm/right_forearm_link.stl" />
      </geometry>
      <material name="white" />
    </visual>
    <collision>
      <origin rpy="0.0 0.0 0.0" xyz="0.0 0.0 -0.09" />
      <geometry>
        <cylinder length="0.18" radius="0.015" />
      </geometry>
    </collision>
  </link>
  <joint name="right_forearm2forearmrot_joint[15]" type="revolute">
    <origin rpy="0.0 0.0 0.0" xyz="0.0 0.0 -0.045" />
    <axis xyz="0.0 0.0 1.0" />
    <parent link="right_forearm_link" />
    <child link="right_forearmrot_link" />
    <limit effort="50.0" lower="-3.14159" upper="3.14159" velocity="15.0" />
    <dynamics damping="0.1" friction="0.1" />
  </joint>
  <link name="right_forearm_pitch_link">
    <inertial>
      <mass value="0.1" />
      <inertia ixx="1.3125e-05" ixy="0.0" ixz="0.0" iyy="1.3125e-05" iyz="0.0" izz="1.125e-05" />
    </inertial>
    <visual>
      <origin rpy="1.57075 0.0 0.0" xyz="0.0 0.0 0.0" />
      <geometry>
        <cylinder length="0.03" radius="0.015" />
      </geometry>
      <material name="blue" />
    </visual>
    <collision>
      <origin rpy="1.57075 0.0 0.0" xyz="0.0 0.0 0.0" />
      <geometry>
        <cylinder length="0.03" radius="0.01" />
      </geometry>
    </collision>
  </link>
  <joint name="right_forearmrot2forearm_pitch_joint[16]" type="revolute">
    <origin rpy="0.0 0.0 0.0" xyz="0.0 0.0 -0.18" />
    <axis xyz="0.0 1.0 0.0" />
    <parent link="right_forearmrot_link" />
    <child link="right_forearm_pitch_link" />
    <limit effort="50.0" lower="-0.229104" upper="0.127816" velocity="15.0" />
    <dynamics damping="0.1" friction="0.1" />
  </joint>
  <link name="right_forearm_roll_link">
    <inertial>
      <mass value="0.1" />
      <inertia ixx="1.3125e-05" ixy="0.0" ixz="0.0" iyy="1.3125e-05" iyz="0.0" izz="1.125e-05" />
    </inertial>
    <visual>
      <origin rpy="0.0 1.57075 0.0" xyz="0.0 0.0 0.0" />
      <geometry>
        <cylinder length="0.03" radius="0.015" />
      </geometry>
      <material name="red" />
    </visual>
    <collision>
      <origin rpy="0.0 1.57075 0.0" xyz="0.0 0.0 0.0" />
      <geometry>
        <cylinder length="0.03" radius="0.01" />
      </geometry>
    </collision>
  </link>
  <joint name="right_forearm_pitch2forearm_roll_joint[17]" type="revolute">
    <origin rpy="0.0 0.0 0.0" xyz="0.0 0.0 0.0" />
    <axis xyz="1.0 0.0 0.0" />
    <parent link="right_forearm_pitch_link" />
    <child link="right_forearm_roll_link" />
    <limit effort="50.0" lower="-0.283791" upper="0.243415" velocity="15.0" />
    <dynamics damping="0.1" friction="0.1" />
  </joint>
  <link name="right_wrist_link">
    <inertial>
      <mass value="0.05" />
      <inertia ixx="0.0001" ixy="0.0" ixz="0.0" iyy="0.0001" iyz="0.0" izz="0.0001" />
    </inertial>
    <visual>
      <origin rpy="0.0 0.0 0.0" xyz="0.0 0.0 -0.025" />
      <geometry>
        <cylinder length="0.05" radius="0.015" />
      </geometry>
      <material name="white" />
    </visual>
    <collision>
      <origin rpy="0.0 0.0 0.0" xyz="0.0 0.0 -0.025" />
      <geometry>
        <cylinder length="0.05" radius="0.015" />
      </geometry>
    </collision>
  </link>
  <joint name="right_forearm_roll2wrist_joint" type="fixed">
    <origin rpy="0.0 0.0 0.0" xyz="0.0 0.0 -0.015" />
    <parent link="right_forearm_roll_link" />
    <child link="right_wrist_link" />
  </joint>
  <link name="dummy_link_18">
    <inertial>
      <mass value="0.001" />
      <inertia ixx="0.000001" ixy="0.0" ixz="0.0" iyy="0.000001" iyz="0.0" izz="0.000001" />
    </inertial>
  </link>
  <joint name="dummy_joint[18]" type="revolute">
    <origin rpy="0.0 0.0 0.0" xyz="0.0 0.0 0.0" />
    <axis xyz="0.0 0.0 1.0" />
    <parent link="right_wrist_link" />
    <child link="dummy_link_18" />
    <limit effort="0.0" lower="0.0" upper="0.0" velocity="0.0" />
  </joint>
  <link name="dummy_link_19">
    <inertial>
      <mass value="0.001" />
      <inertia ixx="0.000001" ixy="0.0" ixz="0.0" iyy="0.000001" iyz="0.0" izz="0.000001" />
    </inertial>
  </link>
  <joint name="dummy_joint[19]" type="revolute">
    <origin rpy="0.0 0.0 0.0" xyz="0.0 0.0 0.0" />
    <axis xyz="0.0 0.0 1.0" />
    <parent link="dummy_link_18" />
    <child link="dummy_link_19" />
    <limit effort="0.0" lower="0.0" upper="0.0" velocity="0.0" />
  </joint>
  <link name="dummy_link_20">
    <inertial>
      <mass value="0.001" />
      <inertia ixx="0.000001" ixy="0.0" ixz="0.0" iyy="0.000001" iyz="0.0" izz="0.000001" />
    </inertial>
  </link>
  <joint name="dummy_joint[20]" type="revolute">
    <origin rpy="0.0 0.0 0.0" xyz="0.0 0.0 0.0" />
    <axis xyz="0.0 0.0 1.0" />
    <parent link="dummy_link_19" />
    <child link="dummy_link_20" />
    <limit effort="0.0" lower="0.0" upper="0.0" velocity="0.0" />
  </joint>
  <link name="dummy_link_21">
    <inertial>
      <mass value="0.001" />
      <inertia ixx="0.000001" ixy="0.0" ixz="0.0" iyy="0.000001" iyz="0.0" izz="0.000001" />
    </inertial>
  </link>
  <joint name="dummy_joint[21]" type="revolute">
    <origin rpy="0.0 0.0 0.0" xyz="0.0 0.0 0.0" />
    <axis xyz="0.0 0.0 1.0" />
    <parent link="dummy_link_20" />
    <child link="dummy_link_21" />
    <limit effort="0.0" lower="0.0" upper="0.0" velocity="0.0" />
  </joint>
  <link name="dummy_link_22">
    <inertial>
      <mass value="0.001" />
      <inertia ixx="0.000001" ixy="0.0" ixz="0.0" iyy="0.000001" iyz="0.0" izz="0.000001" />
    </inertial>
  </link>
  <joint name="dummy_joint[22]" type="revolute">
    <origin rpy="0.0 0.0 0.0" xyz="0.0 0.0 0.0" />
    <axis xyz="0.0 0.0 1.0" />
    <parent link="dummy_link_21" />
    <child link="dummy_link_22" />
    <limit effort="0.0" lower="0.0" upper="0.0" velocity="0.0" />
  </joint>
  <link name="dummy_link_23">
    <inertial>
      <mass value="0.001" />
      <inertia ixx="0.000001" ixy="0.0" ixz="0.0" iyy="0.000001" iyz="0.0" izz="0.000001" />
    </inertial>
  </link>
  <joint name="dummy_joint[23]" type="revolute">
    <origin rpy="0.0 0.0 0.0" xyz="0.0 0.0 0.0" />
    <axis xyz="0.0 0.0 1.0" />
    <parent link="dummy_link_22" />
    <child link="dummy_link_23" />
    <limit effort="0.0" lower="0.0" upper="0.0" velocity="0.0" />
  </joint>
  <link name="dummy_link_24">
    <inertial>
      <mass value="0.001" />
      <inertia ixx="0.000001" ixy="0.0" ixz="0.0" iyy="0.000001" iyz="0.0" izz="0.000001" />
    </inertial>
  </link>
  <joint name="dummy_joint[24]" type="revolute">
    <origin rpy="0.0 0.0 0.0" xyz="0.0 0.0 0.0" />
    <axis xyz="0.0 0.0 1.0" />
    <parent link="dummy_link_23" />
    <child link="dummy_link_24" />
    <limit effort="0.0" lower="0.0" upper="0.0" velocity="0.0" />
  </joint>
  <link name="dummy_link_25">
    <inertial>
      <mass value="0.001" />
      <inertia ixx="0.000001" ixy="0.0" ixz="0.0" iyy="0.000001" iyz="0.0" izz="0.000001" />
    </inertial>
  </link>
  <joint name="dummy_joint[25]" type="revolute">
    <origin rpy="0.0 0.0 0.0" xyz="0.0 0.0 0.0" />
    <axis xyz="0.0 0.0 1.0" />
    <parent link="dummy_link_24" />
    <child link="dummy_link_25" />
    <limit effort="0.0" lower="0.0" upper="0.0" velocity="0.0" />
  </joint>
  <link name="dummy_link_26">
    <inertial>
      <mass value="0.001" />
      <inertia ixx="0.000001" ixy="0.0" ixz="0.0" iyy="0.000001" iyz="0.0" izz="0.000001" />
    </inertial>
  </link>
  <joint name="dummy_joint[26]" type="revolute">
    <origin rpy="0.0 0.0 0.0" xyz="0.0 0.0 0.0" />
    <axis xyz="0.0 0.0 1.0" />
    <parent link="dummy_link_25" />
    <child link="dummy_link_26" />
    <limit effort="0.0" lower="0.0" upper="0.0" velocity="0.0" />
  </joint>
  <link name="dummy_link_27">
    <inertial>
      <mass value="0.001" />
      <inertia ixx="0.000001" ixy="0.0" ixz="0.0" iyy="0.000001" iyz="0.0" izz="0.000001" />
    </inertial>
  </link>
  <joint name="dummy_joint[27]" type="revolute">
    <origin rpy="0.0 0.0 0.0" xyz="0.0 0.0 0.0" />
    <axis xyz="0.0 0.0 1.0" />
    <parent link="dummy_link_26" />
    <child link="dummy_link_27" />
    <limit effort="0.0" lower="0.0" upper="0.0" velocity="0.0" />
  </joint>
  <link name="dummy_link_28">
    <inertial>
      <mass value="0.001" />
      <inertia ixx="0.000001" ixy="0.0" ixz="0.0" iyy="0.000001" iyz="0.0" izz="0.000001" />
    </inertial>
  </link>
  <joint name="dummy_joint[28]" type="revolute">
    <origin rpy="0.0 0.0 0.0" xyz="0.0 0.0 0.0" />
    <axis xyz="0.0 0.0 1.0" />
    <parent link="dummy_link_27" />
    <child link="dummy_link_28" />
    <limit effort="0.0" lower="0.0" upper="0.0" velocity="0.0" />
  </joint>
  <link name="dummy_link_29">
    <inertial>
      <mass value="0.001" />
      <inertia ixx="0.000001" ixy="0.0" ixz="0.0" iyy="0.000001" iyz="0.0" izz="0.000001" />
    </inertial>
  </link>
  <joint name="dummy_joint[29]" type="revolute">
    <origin rpy="0.0 0.0 0.0" xyz="0.0 0.0 0.0" />
    <axis xyz="0.0 0.0 1.0" />
    <parent link="dummy_link_28" />
    <child link="dummy_link_29" />
    <limit effort="0.0" lower="0.0" upper="0.0" velocity="0.0" />
  </joint>
  <link name="dummy_link_30">
    <inertial>
      <mass value="0.001" />
      <inertia ixx="0.000001" ixy="0.0" ixz="0.0" iyy="0.000001" iyz="0.0" izz="0.000001" />
    </inertial>
  </link>
  <joint name="dummy_joint[30]" type="revolute">
    <origin rpy="0.0 0.0 0.0" xyz="0.0 0.0 0.0" />
    <axis xyz="0.0 0.0 1.0" />
    <parent link="dummy_link_29" />
    <child link="dummy_link_30" />
    <limit effort="0.0" lower="0.0" upper="0.0" velocity="0.0" />
  </joint>
  <link name="dummy_link_30a">
    <inertial>
      <mass value="0.001" />
      <inertia ixx="0.000001" ixy="0.0" ixz="0.0" iyy="0.000001" iyz="0.0" izz="0.000001" />
    </inertial>
  </link>
  <joint name="dummy_joint_30a" type="revolute">
    <origin rpy="0.0 0.0 0.0" xyz="0.0 0.0 0.0" />
    <axis xyz="0.0 0.0 1.0" />
    <parent link="dummy_link_30" />
    <child link="dummy_link_30a" />
    <limit effort="0.0" lower="0.0" upper="0.0" velocity="0.0" />
  </joint>
  <link name="dummy_link_30b">
    <inertial>
      <mass value="0.001" />
      <inertia ixx="0.000001" ixy="0.0" ixz="0.0" iyy="0.000001" iyz="0.0" izz="0.000001" />
    </inertial>
  </link>
  <joint name="dummy_joint_30b" type="revolute">
    <origin rpy="0.0 0.0 0.0" xyz="0.0 0.0 0.0" />
    <axis xyz="0.0 0.0 1.0" />
    <parent link="dummy_link_30a" />
    <child link="dummy_link_30b" />
    <limit effort="0.0" lower="0.0" upper="0.0" velocity="0.0" />
  </joint>
  <link name="dummy_link_30c">
    <inertial>
      <mass value="0.001" />
      <inertia ixx="0.000001" ixy="0.0" ixz="0.0" iyy="0.000001" iyz="0.0" izz="0.000001" />
    </inertial>
  </link>
  <joint name="dummy_joint_30c" type="revolute">
    <origin rpy="0.0 0.0 0.0" xyz="0.0 0.0 0.0" />
    <axis xyz="0.0 0.0 1.0" />
    <parent link="dummy_link_30b" />
    <child link="dummy_link_30c" />
    <limit effort="0.0" lower="0.0" upper="0.0" velocity="0.0" />
  </joint>
  <link name="dummy_link_30d">
    <inertial>
      <mass value="0.001" />
      <inertia ixx="0.000001" ixy="0.0" ixz="0.0" iyy="0.000001" iyz="0.0" izz="0.000001" />
    </inertial>
  </link>
  <joint name="dummy_joint_30d" type="revolute">
    <origin rpy="0.0 0.0 0.0" xyz="0.0 0.0 0.0" />
    <axis xyz="0.0 0.0 1.0" />
    <parent link="dummy_link_30c" />
    <child link="dummy_link_30d" />
    <limit effort="0.0" lower="0.0" upper="0.0" velocity="0.0" />
  </joint>
  <link name="dummy_link_30e">
    <inertial>
      <mass value="0.001" />
      <inertia ixx="0.000001" ixy="0.0" ixz="0.0" iyy="0.000001" iyz="0.0" izz="0.000001" />
    </inertial>
  </link>
  <joint name="dummy_joint_30e" type="revolute">
    <origin rpy="0.0 0.0 0.0" xyz="0.0 0.0 0.0" />
    <axis xyz="0.0 0.0 1.0" />
    <parent link="dummy_link_30d" />
    <child link="dummy_link_30e" />
    <limit effort="0.0" lower="0.0" upper="0.0" velocity="0.0" />
  </joint>
  <link name="dummy_link_30f">
    <inertial>
      <mass value="0.001" />
      <inertia ixx="0.000001" ixy="0.0" ixz="0.0" iyy="0.000001" iyz="0.0" izz="0.000001" />
    </inertial>
  </link>
  <joint name="dummy_joint_30f" type="revolute">
    <origin rpy="0.0 0.0 0.0" xyz="0.0 0.0 0.0" />
    <axis xyz="0.0 0.0 1.0" />
    <parent link="dummy_link_30e" />
    <child link="dummy_link_30f" />
    <limit effort="0.0" lower="0.0" upper="0.0" velocity="0.0" />
  </joint>
  <link name="dummy_link_30g">
    <inertial>
      <mass value="0.001" />
      <inertia ixx="0.000001" ixy="0.0" ixz="0.0" iyy="0.000001" iyz="0.0" izz="0.000001" />
    </inertial>
  </link>
  <joint name="dummy_joint_30g" type="revolute">
    <origin rpy="0.0 0.0 0.0" xyz="0.0 0.0 0.0" />
    <axis xyz="0.0 0.0 1.0" />
    <parent link="dummy_link_30f" />
    <child link="dummy_link_30g" />
    <limit effort="0.0" lower="0.0" upper="0.0" velocity="0.0" />
  </joint>
  <link name="dummy_link_30h">
    <inertial>
      <mass value="0.001" />
      <inertia ixx="0.000001" ixy="0.0" ixz="0.0" iyy="0.000001" iyz="0.0" izz="0.000001" />
    </inertial>
  </link>
  <joint name="dummy_joint_30h" type="revolute">
    <origin rpy="0.0 0.0 0.0" xyz="0.0 0.0 0.0" />
    <axis xyz="0.0 0.0 1.0" />
    <parent link="dummy_link_30g" />
    <child link="dummy_link_30h" />
    <limit effort="0.0" lower="0.0" upper="0.0" velocity="0.0" />
  </joint>
  <link name="dummy_link_30i">
    <inertial>
      <mass value="0.001" />
      <inertia ixx="0.000001" ixy="0.0" ixz="0.0" iyy="0.000001" iyz="0.0" izz="0.000001" />
    </inertial>
  </link>
  <joint name="dummy_joint_30i" type="revolute">
    <origin rpy="0.0 0.0 0.0" xyz="0.0 0.0 0.0" />
    <axis xyz="0.0 0.0 1.0" />
    <parent link="dummy_link_30h" />
    <child link="dummy_link_30i" />
    <limit effort="0.0" lower="0.0" upper="0.0" velocity="0.0" />
  </joint>
  <link name="dummy_link_30j">
    <inertial>
      <mass value="0.001" />
      <inertia ixx="0.000001" ixy="0.0" ixz="0.0" iyy="0.000001" iyz="0.0" izz="0.000001" />
    </inertial>
  </link>
  <joint name="dummy_joint_30j" type="revolute">
    <origin rpy="0.0 0.0 0.0" xyz="0.0 0.0 0.0" />
    <axis xyz="0.0 0.0 1.0" />
    <parent link="dummy_link_30i" />
    <child link="dummy_link_30j" />
    <limit effort="0.0" lower="0.0" upper="0.0" velocity="0.0" />
  </joint>
  <link name="right_gripper_base_link">
    <inertial>
      <mass value="0.05" />
      <inertia ixx="0.0001" ixy="0.0" ixz="0.0" iyy="0.0001" iyz="0.0" izz="0.0001" />
    </inertial>
    <visual>
      <origin rpy="3.14159 0.0 0.0" xyz="0.0 0.0 0.0" />
      <geometry>
        <mesh filename="package://RRR_Cater/RX1/rx1_description/meshes/gripper/parts/gripper_base.obj" scale="0.001 0.001 0.001" />
      </geometry>
      <material name="white" />
    </visual>
    <collision>
      <origin rpy="0.0 0.0 0.0" xyz="0.0 0.0 0.0" />
      <geometry>
        <box size="0.05 0.06 0.02" />
      </geometry>
    </collision>
  </link>
  <joint name="right_wrist2gripper_base_joint" type="fixed">
    <origin rpy="0.0 0.0 3.14159" xyz="0.0 0.0 -0.05" />
    <parent link="dummy_link_30j" />
    <child link="right_gripper_base_link" />
  </joint>
  <link name="right_gripper_tip1_link">
    <inertial>
      <mass value="0.01" />
      <inertia ixx="0.00001" ixy="0.0" ixz="0.0" iyy="0.00001" iyz="0.0" izz="0.00001" />
    </inertial>
    <visual>
      <origin rpy="1.5708 3.14159 -1.5708" xyz="-0.09 -0.043 -0.06" />
      <geometry>
        <mesh filename="package://RRR_Cater/RX1/rx1_description/meshes/gripper/parts/gripper_mesh.obj" scale="0.001 0.001 0.001" />
      </geometry>
      <material name="yellow" />
    </visual>
    <collision>
      <origin rpy="0.0 0.0 0.0" xyz="0.0 0.0 0.0" />
      <geometry>
        <box size="0.01 0.05 0.08" />
      </geometry>
    </collision>
  </link>
  <joint name="right_gripper_joint[41]" type="prismatic">
    <origin rpy="0.0 0.0 0.0" xyz="0.0 -0.0605 0.05" />
    <axis xyz="0.0 1.0 0.0" />
    <parent link="right_gripper_base_link" />
    <child link="right_gripper_tip1_link" />
    <limit effort="10.0" lower="-0.05" upper="0.05" velocity="0.1" />
    <dynamics damping="0.1" friction="0.1" />
  </joint>
  <link name="right_gripper_tip2_link">
    <inertial>
      <mass value="0.01" />
      <inertia ixx="0.00001" ixy="0.0" ixz="0.0" iyy="0.00001" iyz="0.0" izz="0.00001" />
    </inertial>
    <visual>
      <origin rpy="1.5708 3.14159 1.5708" xyz="0.09 0.043 -0.06" />
      <geometry>
        <mesh filename="package://RRR_Cater/RX1/rx1_description/meshes/gripper/parts/gripper_mesh.obj" scale="0.001 0.001 0.001" />
      </geometry>
      <material name="yellow" />
    </visual>
    <collision>
      <origin rpy="0.0 0.0 0.0" xyz="0.0 0.0 0.0" />
      <geometry>
        <box size="0.01 0.05 0.08" />
      </geometry>
    </collision>
  </link>
  <joint name="right_gripper_tip2_joint[32]" type="prismatic">
    <origin rpy="0.0 0.0 0.0" xyz="0.0 0.0605 0.05" />
    <axis xyz="0.0 1.0 0.0" />
    <parent link="right_gripper_base_link" />
    <child link="right_gripper_tip2_link" />
    <limit effort="10.0" lower="-0.05" upper="0.05" velocity="0.1" />
    <dynamics damping="0.1" friction="0.1" />
  </joint>
  <link name="left_shoul_base_link">
    <inertial>
      <mass value="0.2" />
      <inertia ixx="0.00011374999999999999" ixy="0.0" ixz="0.0" iyy="0.00011374999999999999" iyz="0.0" izz="4e-05" />
    </inertial>
    <visual>
      <origin rpy="0.0 0.0 0.0" xyz="0.0 0.0 0.0375" />
      <geometry>
        <cylinder length="0.075" radius="0.02" />
      </geometry>
      <material name="white" />
    </visual>
    <collision>
      <origin rpy="0.0 0.0 0.0" xyz="0.0 0.0 0.0375" />
      <geometry>
        <cylinder length="0.075" radius="0.02" />
      </geometry>
    </collision>
  </link>
  <joint name="head_base2left_shoul_base_joint" type="fixed">
    <origin rpy="-1.04706195 0.0 0.0" xyz="0.0 0.12 -0.05" />
    <parent link="head_base_link" />
    <child link="left_shoul_base_link" />
  </joint>
  <link name="left_shoul_link">
    <inertial>
      <mass value="0.2" />
      <inertia ixx="0.00015166666666666668" ixy="0.0" ixz="0.0" iyy="0.00015166666666666668" iyz="0.0" izz="9e-05" />
    </inertial>
    <visual>
      <origin rpy="0.0 0.0 0.0" xyz="0.0 0.0 0.04" />
      <geometry>
        <cylinder length="0.08" radius="0.03" />
      </geometry>
      <material name="red" />
    </visual>
    <collision>
      <origin rpy="0.0 0.0 0.0" xyz="0.0 0.0 0.04" />
      <geometry>
        <cylinder length="0.08" radius="0.03" />
      </geometry>
    </collision>
  </link>
  <joint name="left_shoul_base2shoul_joint[21]" type="revolute">
    <origin rpy="0.0 0.0 0.0" xyz="0.0 0.0 0.075" />
    <axis xyz="0.0 0.0 1.0" />
    <parent link="left_shoul_base_link" />
    <child link="left_shoul_link" />
    <limit effort="50.0" lower="-1.483355" upper="0.578286" velocity="15.0" />
    <dynamics damping="0.5" friction="0.1" />
  </joint>
  <link name="left_shoul_rot_link">
    <inertial>
      <mass value="0.2" />
      <inertia ixx="7.166666666666667e-05" ixy="0.0" ixz="0.0" iyy="7.166666666666667e-05" iyz="0.0" izz="9e-05" />
    </inertial>
    <visual>
      <origin rpy="0.0 1.57075 0.0" xyz="0.0 0.0 0.0" />
      <geometry>
        <cylinder length="0.04" radius="0.03" />
      </geometry>
      <material name="blue" />
    </visual>
    <collision>
      <origin rpy="0.0 1.57075 0.0" xyz="0.0 0.0 0.0" />
      <geometry>
        <cylinder length="0.04" radius="0.03" />
      </geometry>
    </collision>
  </link>
  <joint name="left_shoul2shoul_rot_joint[22]" type="revolute">
    <origin rpy="1.04706195 0.0 0.0" xyz="0.0 0.0 0.08" />
    <axis xyz="1.0 0.0 0.0" />
    <parent link="left_shoul_link" />
    <child link="left_shoul_rot_link" />
    <limit effort="50.0" lower="-0.047066" upper="1.997238" velocity="15.0" />
    <dynamics damping="0.1" friction="0.1" />
  </joint>
  <link name="left_upper_arm_link">
    <inertial>
      <mass value="0.1" />
      <inertia ixx="0.00026469309370525756" ixy="0.0" ixz="0.0" iyy="0.000295128481794064" iyz="0.0" izz="9.863136459929792e-05" />
    </inertial>
    <visual>
      <origin rpy="0.0 0.0 0.0" xyz="0.0 0.0 0.0" />
      <geometry>
        <mesh filename="package://RRR_Cater/RX1/rx1_description/meshes/left_arm/left_upper_arm_link.stl" />
      </geometry>
      <material name="white" />
    </visual>
    <collision>
      <origin rpy="0.0 0.0 0.0" xyz="0.0 0.0 0.0" />
      <geometry>
        <mesh filename="package://RRR_Cater/RX1/rx1_description/meshes/left_arm/left_upper_arm_link.stl" />
      </geometry>
    </collision>
  </link>
  <joint name="left_shoul_rot2upper_arm_joint" type="fixed">
    <origin rpy="0.0 0.0 0.0" xyz="0.0 0.0 -0.0625" />
    <parent link="left_shoul_rot_link" />
    <child link="left_upper_arm_link" />
  </joint>
  <link name="left_armrot_link">
    <inertial>
      <mass value="0.1" />
      <inertia ixx="0.000573437191095085" ixy="0.0" ixz="0.0" iyy="0.0005528666771680125" iyz="0.0" izz="8.463720159643078e-05" />
    </inertial>
    <visual>
      <origin rpy="0.0 0.0 0.0" xyz="0.0 0.0 -0.11" />
      <geometry>
        <mesh filename="package://RRR_Cater/RX1/rx1_description/meshes/left_arm/left_elbow_link.stl" />
      </geometry>
      <material name="white" />
    </visual>
    <collision>
      <origin rpy="0.0 0.0 0.0" xyz="0.0 0.0 -0.11" />
      <geometry>
        <cylinder length="0.22" radius="0.03" />
      </geometry>
    </collision>
  </link>
  <joint name="left_arm2armrot_joint[23]" type="revolute">
    <origin rpy="0.0 0.0 0.0" xyz="0.0 0.0 -0.0625" />
    <axis xyz="0.0 0.0 1.0" />
    <parent link="left_upper_arm_link" />
    <child link="left_armrot_link" />
    <limit effort="50.0" lower="-2.094395" upper="2.094395" velocity="15.0" />
    <dynamics damping="0.1" friction="0.1" />
  </joint>
  <link name="left_elbow_link">
    <inertial>
      <mass value="0.1" />
      <inertia ixx="7.583333333333334e-05" ixy="0.0" ixz="0.0" iyy="7.583333333333334e-05" iyz="0.0" izz="4.5e-05" />
    </inertial>
    <visual>
      <origin rpy="0.0 -1.57075 -1.57075" xyz="0.0 0.0 0.0" />
      <geometry>
        <cylinder length="0.08" radius="0.03" />
      </geometry>
      <material name="blue" />
    </visual>
    <collision>
      <origin rpy="0.0 -1.57075 -1.57075" xyz="0.0 0.0 0.0" />
      <geometry>
        <cylinder length="0.08" radius="0.03" />
      </geometry>
    </collision>
  </link>
  <joint name="left_armrot2elbow_joint[24]" type="revolute">
    <origin rpy="0.0 0.0 0.0" xyz="0.0 0.0 -0.22" />
    <axis xyz="0.0 1.0 0.0" />
    <parent link="left_armrot_link" />
    <child link="left_elbow_link" />
    <limit effort="50.0" lower="-2.094395" upper="0.0" velocity="15.0" />
    <dynamics damping="0.1" friction="0.1" />
  </joint>
  <link name="left_forearm_link">
    <inertial>
      <mass value="0.1" />
      <inertia ixx="9e-05" ixy="0.0" ixz="0.0" iyy="9e-05" iyz="0.0" izz="4.5e-05" />
    </inertial>
    <visual>
      <origin rpy="0.0 0.0 0.0" xyz="0.0 0.0 0.0" />
      <geometry>
        <cylinder length="0.09" radius="0.03" />
      </geometry>
      <material name="white" />
    </visual>
    <collision>
      <origin rpy="0.0 0.0 0.0" xyz="0.0 0.0 0.0" />
      <geometry>
        <cylinder length="0.09" radius="0.03" />
      </geometry>
    </collision>
  </link>
  <joint name="left_elbow2forearm_joint" type="fixed">
    <origin rpy="0.0 0.0 0.0" xyz="0.0 0.0 -0.045" />
    <parent link="left_elbow_link" />
    <child link="left_forearm_link" />
  </joint>
  <link name="left_forearmrot_link">
    <inertial>
      <mass value="0.1" />
      <inertia ixx="0.00038840639708807395" ixy="0.0" ixz="0.0" iyy="0.00039995180679971244" iyz="0.0" izz="0.00011242609109381833" />
    </inertial>
    <visual>
      <origin rpy="0.0 0.0 0.0" xyz="0.0 0.0 -0.09" />
      <geometry>
        <mesh filename="package://RRR_Cater/RX1/rx1_description/meshes/left_arm/left_forearm_link.stl" />
      </geometry>
      <material name="white" />
    </visual>
    <collision>
      <origin rpy="0.0 0.0 0.0" xyz="0.0 0.0 -0.09" />
      <geometry>
        <cylinder length="0.18" radius="0.015" />
      </geometry>
    </collision>
  </link>
  <joint name="left_forearm2forearmrot_joint[25]" type="revolute">
    <origin rpy="0.0 0.0 0.0" xyz="0.0 0.0 -0.045" />
    <axis xyz="0.0 0.0 1.0" />
    <parent link="left_forearm_link" />
    <child link="left_forearmrot_link" />
    <limit effort="50.0" lower="-3.14159" upper="3.14159" velocity="15.0" />
    <dynamics damping="0.1" friction="0.1" />
  </joint>
  <link name="left_forearm_pitch_link">
    <inertial>
      <mass value="0.1" />
      <inertia ixx="1.3125e-05" ixy="0.0" ixz="0.0" iyy="1.3125e-05" iyz="0.0" izz="1.125e-05" />
    </inertial>
    <visual>
      <origin rpy="-1.57075 0.0 0.0" xyz="0.0 0.0 0.0" />
      <geometry>
        <cylinder length="0.03" radius="0.015" />
      </geometry>
      <material name="blue" />
    </visual>
    <collision>
      <origin rpy="-1.57075 0.0 0.0" xyz="0.0 0.0 0.0" />
      <geometry>
        <cylinder length="0.03" radius="0.01" />
      </geometry>
    </collision>
  </link>
  <joint name="left_forearmrot2forearm_pitch_joint[26]" type="revolute">
    <origin rpy="0.0 0.0 0.0" xyz="0.0 0.0 -0.18" />
    <axis xyz="0.0 1.0 0.0" />
    <parent link="left_forearmrot_link" />
    <child link="left_forearm_pitch_link" />
    <limit effort="50.0" lower="-0.229104" upper="0.127816" velocity="15.0" />
    <dynamics damping="0.1" friction="0.1" />
  </joint>
  <link name="left_forearm_roll_link">
    <inertial>
      <mass value="0.1" />
      <inertia ixx="1.3125e-05" ixy="0.0" ixz="0.0" iyy="1.3125e-05" iyz="0.0" izz="1.125e-05" />
    </inertial>
    <visual>
      <origin rpy="0.0 -1.57075 0.0" xyz="0.0 0.0 0.0" />
      <geometry>
        <cylinder length="0.03" radius="0.015" />
      </geometry>
      <material name="red" />
    </visual>
    <collision>
      <origin rpy="0.0 -1.57075 0.0" xyz="0.0 0.0 0.0" />
      <geometry>
        <cylinder length="0.03" radius="0.01" />
      </geometry>
    </collision>
  </link>
  <joint name="left_forearm_pitch2forearm_roll_joint[27]" type="revolute">
    <origin rpy="0.0 0.0 0.0" xyz="0.0 0.0 0.0" />
    <axis xyz="1.0 0.0 0.0" />
    <parent link="left_forearm_pitch_link" />
    <child link="left_forearm_roll_link" />
    <limit effort="50.0" lower="-0.283791" upper="0.243415" velocity="15.0" />
    <dynamics damping="0.1" friction="0.1" />
  </joint>
  <link name="left_wrist_link">
    <inertial>
      <mass value="0.05" />
      <inertia ixx="0.0001" ixy="0.0" ixz="0.0" iyy="0.0001" iyz="0.0" izz="0.0001" />
    </inertial>
    <visual>
      <origin rpy="0.0 0.0 0.0" xyz="0.0 0.0 -0.025" />
      <geometry>
        <cylinder length="0.05" radius="0.015" />
      </geometry>
      <material name="white" />
    </visual>
    <collision>
      <origin rpy="0.0 0.0 0.0" xyz="0.0 0.0 -0.025" />
      <geometry>
        <cylinder length="0.05" radius="0.015" />
      </geometry>
    </collision>
  </link>
  <joint name="left_forearm_roll2wrist_joint" type="fixed">
    <origin rpy="0.0 0.0 0.0" xyz="0.0 0.0 -0.015" />
    <parent link="left_forearm_roll_link" />
    <child link="left_wrist_link" />
  </joint>
  <link name="dummy_link_40">
    <inertial>
      <mass value="0.001" />
      <inertia ixx="0.000001" ixy="0.0" ixz="0.0" iyy="0.000001" iyz="0.0" izz="0.000001" />
    </inertial>
  </link>
  <joint name="dummy_joint_40" type="revolute">
    <origin rpy="0.0 0.0 0.0" xyz="0.0 0.0 0.0" />
    <axis xyz="0.0 1.0 0.0" />
    <parent link="left_wrist_link" />
    <child link="dummy_link_40" />
    <limit effort="0.0" lower="0.0" upper="0.0" velocity="0.0" />
  </joint>
  <link name="left_gripper_base_link">
    <inertial>
      <mass value="0.05" />
      <inertia ixx="0.0001" ixy="0.0" ixz="0.0" iyy="0.0001" iyz="0.0" izz="0.0001" />
    </inertial>
    <visual>
      <origin rpy="3.14159 0.0 0.0" xyz="0.0 0.0 0.0" />
      <geometry>
        <mesh filename="package://RRR_Cater/RX1/rx1_description/meshes/gripper/parts/gripper_base.obj" scale="0.001 0.001 0.001" />
      </geometry>
      <material name="white" />
    </visual>
    <collision>
      <origin rpy="0.0 0.0 0.0" xyz="0.0 0.0 0.0" />
      <geometry>
        <box size="0.05 0.06 0.02" />
      </geometry>
    </collision>
  </link>
  <joint name="left_wrist2gripper_base_joint" type="fixed">
    <origin rpy="0.0 0.0 0.0" xyz="0.0 0.0 -0.05" />
    <parent link="dummy_link_40" />
    <child link="left_gripper_base_link" />
  </joint>
  <link name="left_gripper_tip1_link">
    <inertial>
      <mass value="0.01" />
      <inertia ixx="0.00001" ixy="0.0" ixz="0.0" iyy="0.00001" iyz="0.0" izz="0.00001" />
    </inertial>
    <visual>
      <origin rpy="1.5708 3.14159 -1.5708" xyz="-0.09 -0.06 -0.06" />
      <geometry>
        <mesh filename="package://RRR_Cater/RX1/rx1_description/meshes/gripper/parts/gripper_mesh.obj" scale="0.001 0.001 0.001" />
      </geometry>
      <material name="yellow" />
    </visual>
    <collision>
      <origin rpy="0.0 0.0 0.0" xyz="0.0 0.0 0.0" />
      <geometry>
        <box size="0.01 0.05 0.08" />
      </geometry>
    </collision>
  </link>
  <joint name="left_gripper_joint[31]" type="prismatic">
    <origin rpy="0.0 0.0 0.0" xyz="0.0 -0.0605 0.05" />
    <axis xyz="0.0 1.0 0.0" />
    <parent link="left_gripper_base_link" />
    <child link="left_gripper_tip1_link" />
    <limit effort="10.0" lower="-0.05" upper="0.05" velocity="0.1" />
    <dynamics damping="0.1" friction="0.1" />
  </joint>
  <link name="left_gripper_tip2_link">
    <inertial>
      <mass value="0.01" />
      <inertia ixx="0.00001" ixy="0.0" ixz="0.0" iyy="0.00001" iyz="0.0" izz="0.00001" />
    </inertial>
    <visual>
      <origin rpy="1.5708 3.14159 1.5708" xyz="0.09 0.043 -0.06" />
      <geometry>
        <mesh filename="package://RRR_Cater/RX1/rx1_description/meshes/gripper/parts/gripper_mesh.obj" scale="0.001 0.001 0.001" />
      </geometry>
      <material name="yellow" />
    </visual>
    <collision>
      <origin rpy="0.0 0.0 0.0" xyz="0.0 0.0 0.0" />
      <geometry>
        <box size="0.01 0.05 0.08" />
      </geometry>
    </collision>
  </link>
  <joint name="left_gripper_tip2_joint[28]" type="prismatic">
    <origin rpy="0.0 0.0 0.0" xyz="0.0 0.0605 0.05" />
    <axis xyz="0.0 1.0 0.0" />
    <parent link="left_gripper_base_link" />
    <child link="left_gripper_tip2_link" />
    <limit effort="10.0" lower="-0.05" upper="0.05" velocity="0.1" />
    <dynamics damping="0.1" friction="0.1" />
  </joint>
  <link name="lift_platform_link">
    <inertial>
      <mass value="1.0" />
      <inertia ixx="0.01" ixy="0.0" ixz="0.0" iyy="0.01" iyz="0.0" izz="0.01" />
    </inertial>
    <visual>
      <origin rpy="0 0 0" xyz="0 0 0" />
      <geometry>
        <mesh filename="package://RRR_Cater/RX1/rx1_description/meshes/lift1.obj" scale="0.001 0.001 0.001" />
      </geometry>
      <material name="lift_material">
        <color rgba="0.7 0.7 0.7 1.0" />
      </material>
    </visual>
    <collision>
      <origin rpy="0 0 0" xyz="0 0 0" />
      <geometry>
        <mesh filename="package://RRR_Cater/RX1/rx1_description/meshes/lift1.obj" scale="0.001 0.001 0.001" />
      </geometry>
    </collision>
  </link>
  <joint name="base_to_lift_joint" type="prismatic">
    <origin rpy="0 0 0" xyz="-0.041 0 0.99" />
    <axis xyz="0 0 1" />
    <limit effort="1000" lower="-0.8" upper="0" velocity="1.0" />
    <parent link="base_link" />
    <child link="lift_platform_link" />
  </joint>
  <link name="nema42_link">
    <inertial>
      <origin rpy="0 0 0" xyz="0 -0.001762 0.000103" />
      <mass value="12.0" />
      <inertia ixx="0.01" ixy="0.0" ixz="0.0" iyy="0.01" iyz="0.0" izz="0.01" />
    </inertial>
    <visual>
      <origin rpy="0 0 0" xyz="0 0 0" />
      <geometry>
        <mesh filename="package://RRR_Cater/RX1/rx1_description/meshes/NEMA42.obj" scale="0.001 0.001 0.001" />
      </geometry>
      <material name="nema42_material">
        <color rgba="0.3 0.3 0.3 1.0" />
      </material>
    </visual>
    <collision>
      <origin rpy="0 0 0" xyz="0 0 0" />
      <geometry>
        <mesh filename="package://RRR_Cater/RX1/rx1_description/meshes/NEMA42.obj" scale="0.001 0.001 0.001" />
      </geometry>
    </collision>
  </link>
  <joint name="base_to_nema42_joint" type="revolute">
    <origin rpy="0 0 1.5708" xyz="-0.275 0.065 -0.155" />
    <axis xyz="0 0 1" />
    <limit effort="0" lower="0" upper="0" velocity="0" />
    <parent link="base_link" />
    <child link="nema42_link" />
  </joint>
  <link name="xp1000_link">
    <inertial>
      <origin rpy="0 0 0" xyz="-0.015573 0.009130 -0.004743" />
      <mass value="14.0" />
      <inertia ixx="0.01" ixy="0.0" ixz="0.0" iyy="0.01" iyz="0.0" izz="0.01" />
    </inertial>
    <visual>
      <origin rpy="0 0 0" xyz="0 0 0" />
      <geometry>
        <mesh filename="package://RRR_Cater/RX1/rx1_description/meshes/XP1000.obj" scale="0.001 0.001 0.001" />
      </geometry>
      <material name="xp1000_material">
        <color rgba="0.7 0.7 0.7 1.0" />
      </material>
    </visual>
    <collision>
      <origin rpy="0 0 0" xyz="0 0 0" />
      <geometry>
        <mesh filename="package://RRR_Cater/RX1/rx1_description/meshes/XP1000.obj" scale="0.001 0.001 0.001" />
      </geometry>
    </collision>
  </link>
  <joint name="base_to_xp1000_joint" type="revolute">
    <origin rpy="1.5708 0 1.5708" xyz="-0.07 0 -0.3666" />
    <axis xyz="0 0 1" />
    <limit effort="0" lower="0" upper="0" velocity="0" />
    <parent link="base_link" />
    <child link="xp1000_link" />
  </joint>
  <link name="cater_platform_link">
    <inertial>
      <mass value="2.0" />
      <inertia ixx="0.1" ixy="0.0" ixz="0.0" iyy="0.1" iyz="0.0" izz="0.1" />
    </inertial>
  </link>
  <joint name="base_to_cater_joint" type="fixed">
    <origin rpy="0 0 0" xyz="-0.1200 0.0000 0.0000" />
    <parent link="base_link" />
    <child link="cater_platform_link" />
  </joint>
  <link name="ballast_front_weight"><inertial><origin xyz="0 0 0" rpy="0 0 0" /><mass value="4.11" /><inertia ixx="0.05" ixy="0.0" ixz="0.0" iyy="0.05" iyz="0.0" izz="0.05" /></inertial></link><joint name="cater_to_ballast_joint" type="fixed"><origin rpy="0 0 0" xyz="1.0000 0.0000 0.0000" /><parent link="cater_platform_link" /><child link="ballast_front_weight" /></joint><link name="cater_frame_link">
    <inertial>
      <mass value="0.01" />
      <inertia ixx="0.05" ixy="0.0" ixz="0.0" iyy="0.05" iyz="0.0" izz="0.05" />
    </inertial>
    <visual>
      <origin rpy="0 0 0" xyz="0 0 0" />
      <geometry>
        <mesh filename="package://RRR_Cater/RX1/rx1_description/meshes/Cater_frame_matched.obj" scale="0.001 0.001 0.001" />
      </geometry>
      <material name="cater_frame_material">
        <color rgba="0.9 0.6 0.2 1.0" />
      </material>
    </visual>
  </link>
  <link name="cater_frame_upper_mass">
    <inertial>
      <origin xyz="0 0 0.15" rpy="0 0 0" />
      <mass value="4.0" />
      <inertia ixx="0.05" ixy="0.0" ixz="0.0" iyy="0.05" iyz="0.0" izz="0.05" />
    </inertial>
  </link>
  <joint name="cater_frame_to_upper_mass" type="fixed">
    <origin rpy="0 0 0" xyz="0 0 0" />
    <parent link="cater_frame_link" />
    <child link="cater_frame_upper_mass" />
  </joint>
  <link name="cater_frame_lower_mass">
    <inertial>
      <origin xyz="0 0 -0.1" rpy="0 0 0" />
      <mass value="20.0" />
      <inertia ixx="0.3" ixy="0.0" ixz="0.0" iyy="0.3" iyz="0.0" izz="0.3" />
    </inertial>
  </link>
  <joint name="cater_frame_to_lower_mass" type="fixed">
    <origin rpy="0 0 0" xyz="0 0 0" />
    <parent link="cater_frame_link" />
    <child link="cater_frame_lower_mass" />
  </joint>
  <link name="center_ballast_weight">
    <inertial>
      <origin xyz="0 0 -0.55" rpy="0 0 0" />
      <mass value="25.0" />
      <inertia ixx="0.625" ixy="0.0" ixz="0.0" iyy="0.625" iyz="0.0" izz="0.625" />
    </inertial>
  </link>
  <joint name="cater_to_center_ballast" type="fixed">
    <origin rpy="0 0 0" xyz="0 0 0" />
    <parent link="cater_platform_link" />
    <child link="center_ballast_weight" />
  </joint>
  <joint name="cater_to_frame_joint" type="fixed">
    <origin rpy="0 0 0" xyz="0 0 0" />
    <parent link="cater_platform_link" />
    <child link="cater_frame_link" />
  </joint>
  <link name="caster_front_left_pivot_link">
    <inertial>
      <origin xyz="0.06600000 0.00000000 0.0" rpy="0 0 0" />
      <mass value="0.3" />
      <inertia ixx="0.003" ixy="0.0" ixz="0.0" iyx="0.0" iyy="0.003" iyz="0.0" izx="0.0" izy="0.0" izz="0.003" />
    </inertial>
    <visual>
      <origin rpy="1.57057 3.14159 0" xyz="0.02600000 0.00000000 0.0" />
      <geometry>
        <mesh filename="package://RRR_Cater/RX1/rx1_description/meshes/pivot.obj" scale="0.663919 0.663919 0.663919" />
      </geometry>
      <material name="black">
        <color rgba="0.1 0.1 0.1 1.0" />
      </material>
    </visual>
    <collision>
      <origin xyz="0.02600000 0.00000000 0.0" rpy="0 0 0" /><geometry><cylinder radius="0.02" length="0.04" /></geometry></collision>
      <visual>
      <origin rpy="0 0 0" xyz="0 0 0.3" />
      <geometry>
        <cylinder length="0.6" radius="0.01" />
      </geometry>
      <material name="red" />
    </visual>
</link>
  <link name="caster_front_left_mount_link">
    <inertial>
      <origin xyz="0 0 0" rpy="0 0 0" />
      <mass value="0.5" />
      <inertia ixx="0.001" ixy="0.0" ixz="0.0" iyx="0.0" iyy="0.001" iyz="0.0" izx="0.0" izy="0.0" izz="0.001" />
    </inertial>
  </link>
  <joint name="caster_front_left_mount_joint" type="fixed">
    <origin xyz="0.339437 0.21806400 -0.542585" rpy="0 0 0" />
    <parent link="cater_platform_link" />
    <child link="caster_front_left_mount_link" />
  </joint>
  <joint name="caster_front_left_pivot_joint" type="continuous">
    <origin rpy="0 0 0" xyz="-0.04955 0.00200000 -0.0266" />
    <axis xyz="0 0 -1" />
    <parent link="caster_front_left_mount_link" />
    <child link="caster_front_left_pivot_link" />
    <dynamics damping="1.0" friction="0.0" />
  </joint>
  <link name="caster_front_left_wheel_link">
    <inertial>
      <mass value="1.0" />
      <inertia ixx="0.01" ixy="0.0" ixz="0.0" iyx="0.0" iyy="0.01" iyz="0.0" izx="0.0" izy="0.0" izz="0.01" />
    </inertial>
    <visual>
      <origin rpy="1.57057 0.0 0" xyz="0 0 0" />
      <geometry>
        <mesh filename="package://RRR_Cater/RX1/rx1_description/meshes/caster_wheel.obj" scale="0.657895 0.657895 0.657895" />
      </geometry>
      <material name="black">
        <color rgba="0.1 0.1 0.1 1.0" />
      </material>
    </visual>
    <collision>
      <origin rpy="1.57057 0.0 0" xyz="0 0 0" />
      <geometry>
        <cylinder length="0.025" radius="0.05" />
      </geometry>
      <surface>
        <contact>
          <collide_bitmask value="0xFFFF" />
        </contact>
        <friction>
          <ode>
            <mu value="1.0" />
            <mu2 value="1.0" />
            <slip1 value="0.0" />
            <slip2 value="0.0" />
          </ode>
        </friction>
      </surface>
    </collision>
  </link>
  <joint name="caster_front_left_axle_joint" type="continuous">
    <origin rpy="0 0 0" xyz="0.02600000 0.00000000 -0.0020659999999999984" />
    <axis xyz="0 1 0" />
    <parent link="caster_front_left_pivot_link" />
    <child link="caster_front_left_wheel_link" />
    <dynamics damping="0.001" friction="0.0" />
  </joint>
  <link name="caster_front_right_pivot_link">
    <inertial>
      <origin xyz="0.06600000 0.00000000 0.0" rpy="0 0 0" />
      <mass value="0.3" />
      <inertia ixx="0.003" ixy="0.0" ixz="0.0" iyx="0.0" iyy="0.003" iyz="0.0" izx="0.0" izy="0.0" izz="0.003" />
    </inertial>
    <visual>
      <origin rpy="1.57057 3.14159 0" xyz="0.02600000 0.00000000 0.0" />
      <geometry>
        <mesh filename="package://RRR_Cater/RX1/rx1_description/meshes/pivot.obj" scale="0.663919 0.663919 0.663919" />
      </geometry>
      <material name="black">
        <color rgba="0.1 0.1 0.1 1.0" />
      </material>
    </visual>
    <collision>
      <origin xyz="0.02600000 0.00000000 0.0" rpy="0 0 0" /><geometry><cylinder radius="0.02" length="0.04" /></geometry></collision>
      <visual>
      <origin rpy="0 0 0" xyz="0 0 0.3" />
      <geometry>
        <cylinder length="0.6" radius="0.01" />
      </geometry>
      <material name="red" />
    </visual>
</link>
  <link name="caster_front_right_mount_link">
    <inertial>
      <origin xyz="0 0 0" rpy="0 0 0" />
      <mass value="0.5" />
      <inertia ixx="0.001" ixy="0.0" ixz="0.0" iyx="0.0" iyy="0.001" iyz="0.0" izx="0.0" izy="0.0" izz="0.001" />
    </inertial>
  </link>
  <joint name="caster_front_right_mount_joint" type="fixed">
    <origin xyz="0.339437 -0.21806400 -0.542585" rpy="0 0 0" />
    <parent link="cater_platform_link" />
    <child link="caster_front_right_mount_link" />
  </joint>
  <joint name="caster_front_right_pivot_joint" type="continuous">
    <origin rpy="0 0 0" xyz="-0.04955 -0.00200000 -0.0266" />
    <axis xyz="0 0 -1" />
    <parent link="caster_front_right_mount_link" />
    <child link="caster_front_right_pivot_link" />
    <dynamics damping="1.0" friction="0.0" />
  </joint>
  <link name="caster_front_right_wheel_link">
    <inertial>
      <mass value="1.0" />
      <inertia ixx="0.01" ixy="0.0" ixz="0.0" iyx="0.0" iyy="0.01" iyz="0.0" izx="0.0" izy="0.0" izz="0.01" />
    </inertial>
    <visual>
      <origin rpy="1.57057 0.0 0" xyz="0 0 0" />
      <geometry>
        <mesh filename="package://RRR_Cater/RX1/rx1_description/meshes/caster_wheel.obj" scale="0.657895 0.657895 0.657895" />
      </geometry>
      <material name="black">
        <color rgba="0.1 0.1 0.1 1.0" />
      </material>
    </visual>
    <collision>
      <origin rpy="1.57057 0.0 0" xyz="0 0 0" />
      <geometry>
        <cylinder length="0.025" radius="0.05" />
      </geometry>
      <surface>
        <contact>
          <collide_bitmask value="0xFFFF" />
        </contact>
        <friction>
          <ode>
            <mu value="1.0" />
            <mu2 value="1.0" />
            <slip1 value="0.0" />
            <slip2 value="0.0" />
          </ode>
        </friction>
      </surface>
    </collision>
  </link>
  <joint name="caster_front_right_axle_joint" type="continuous">
    <origin rpy="0 0 0" xyz="0.02600000 0.00000000 -0.0020659999999999984" />
    <axis xyz="0 1 0" />
    <parent link="caster_front_right_pivot_link" />
    <child link="caster_front_right_wheel_link" />
    <dynamics damping="0.001" friction="0.0" />
  </joint>
  <link name="caster_rear_left_pivot_link">
    <inertial>
      <origin xyz="0.02510000 0.00000000 0.0" rpy="0 0 0" />
      <mass value="0.3" />
      <inertia ixx="0.003" ixy="0.0" ixz="0.0" iyx="0.0" iyy="0.003" iyz="0.0" izx="0.0" izy="0.0" izz="0.003" />
    </inertial>
    <visual>
      <origin rpy="1.57057 3.14159 0" xyz="0.02510000 0.00000000 0.0" />
      <geometry>
        <mesh filename="package://RRR_Cater/RX1/rx1_description/meshes/pivot.obj" scale="0.663919 0.663919 0.663919" />
      </geometry>
      <material name="black">
        <color rgba="0.1 0.1 0.1 1.0" />
      </material>
    </visual>
    <collision>
      <origin xyz="0.02510000 0.00000000 0.0" rpy="0 0 0" /><geometry><cylinder radius="0.02" length="0.04" /></geometry></collision>
      <visual>
      <origin rpy="0 0 0" xyz="0 0 0.3" />
      <geometry>
        <cylinder length="0.6" radius="0.01" />
      </geometry>
      <material name="red" />
    </visual>
</link>
  <link name="caster_rear_left_mount_link">
    <inertial>
      <origin xyz="0 0 0" rpy="0 0 0" />
      <mass value="0.5" />
      <inertia ixx="0.001" ixy="0.0" ixz="0.0" iyx="0.0" iyy="0.001" iyz="0.0" izx="0.0" izy="0.0" izz="0.001" />
    </inertial>
  </link>
  <joint name="caster_rear_left_mount_joint" type="fixed">
    <origin xyz="-0.110563 0.21806400 -0.542585" rpy="0 0 0" />
    <parent link="cater_platform_link" />
    <child link="caster_rear_left_mount_link" />
  </joint>
  <joint name="caster_rear_left_pivot_joint" type="continuous">
    <origin rpy="0 0 0" xyz="-0.0604533 0.00200000 -0.0266" />
    <axis xyz="0 0 -1" />
    <parent link="caster_rear_left_mount_link" />
    <child link="caster_rear_left_pivot_link" />
    <dynamics damping="1.0" friction="0.0" />
  </joint>
  <link name="caster_rear_left_wheel_link">
    <inertial>
      <mass value="1.0" />
      <inertia ixx="0.01" ixy="0.0" ixz="0.0" iyx="0.0" iyy="0.01" iyz="0.0" izx="0.0" izy="0.0" izz="0.01" />
    </inertial>
    <visual>
      <origin rpy="1.57057 0.0 0" xyz="0 0 0" />
      <geometry>
        <mesh filename="package://RRR_Cater/RX1/rx1_description/meshes/caster_wheel.obj" scale="0.657895 0.657895 0.657895" />
      </geometry>
      <material name="black">
        <color rgba="0.1 0.1 0.1 1.0" />
      </material>
    </visual>
    <collision>
      <origin rpy="1.57057 0.0 0" xyz="0 0 0" />
      <geometry>
        <cylinder length="0.025" radius="0.05" />
      </geometry>
      <surface>
        <contact>
          <collide_bitmask value="0xFFFF" />
        </contact>
        <friction>
          <ode>
            <mu value="1.0" />
            <mu2 value="1.0" />
            <slip1 value="0.0" />
            <slip2 value="0.0" />
          </ode>
        </friction>
      </surface>
    </collision>
  </link>
  <joint name="caster_rear_left_axle_joint" type="continuous">
    <origin rpy="0 0 0" xyz="0.02510000 0.00000000 -0.0020659999999999984" />
    <axis xyz="0 1 0" />
    <parent link="caster_rear_left_pivot_link" />
    <child link="caster_rear_left_wheel_link" />
    <dynamics damping="0.001" friction="0.0" />
  </joint>
  <link name="caster_rear_right_pivot_link">
    <inertial>
      <origin xyz="0.02510000 0.00000000 0.0" rpy="0 0 0" />
      <mass value="0.3" />
      <inertia ixx="0.003" ixy="0.0" ixz="0.0" iyx="0.0" iyy="0.003" iyz="0.0" izx="0.0" izy="0.0" izz="0.003" />
    </inertial>
    <visual>
      <origin rpy="1.57057 3.14159 0" xyz="0.02510000 0.00000000 0.0" />
      <geometry>
        <mesh filename="package://RRR_Cater/RX1/rx1_description/meshes/pivot.obj" scale="0.663919 0.663919 0.663919" />
      </geometry>
      <material name="black">
        <color rgba="0.1 0.1 0.1 1.0" />
      </material>
    </visual>
    <collision>
      <origin xyz="0.02510000 0.00000000 0.0" rpy="0 0 0" /><geometry><cylinder radius="0.02" length="0.04" /></geometry></collision>
      <visual>
      <origin rpy="0 0 0" xyz="0 0 0.3" />
      <geometry>
        <cylinder length="0.6" radius="0.01" />
      </geometry>
      <material name="red" />
    </visual>
</link>
  <link name="caster_rear_right_mount_link">
    <inertial>
      <origin xyz="0 0 0" rpy="0 0 0" />
      <mass value="0.5" />
      <inertia ixx="0.001" ixy="0.0" ixz="0.0" iyx="0.0" iyy="0.001" iyz="0.0" izx="0.0" izy="0.0" izz="0.001" />
    </inertial>
  </link>
  <joint name="caster_rear_right_mount_joint" type="fixed">
    <origin xyz="-0.110563 -0.21806400 -0.542585" rpy="0 0 0" />
    <parent link="cater_platform_link" />
    <child link="caster_rear_right_mount_link" />
  </joint>
  <joint name="caster_rear_right_pivot_joint" type="continuous">
    <origin rpy="0 0 0" xyz="-0.0604533 -0.00200000 -0.0266" />
    <axis xyz="0 0 -1" />
    <parent link="caster_rear_right_mount_link" />
    <child link="caster_rear_right_pivot_link" />
    <dynamics damping="1.0" friction="0.0" />
  </joint>
  <link name="caster_rear_right_wheel_link">
    <inertial>
      <mass value="1.0" />
      <inertia ixx="0.01" ixy="0.0" ixz="0.0" iyx="0.0" iyy="0.01" iyz="0.0" izx="0.0" izy="0.0" izz="0.01" />
    </inertial>
    <visual>
      <origin rpy="1.57057 0.0 0" xyz="0 0 0" />
      <geometry>
        <mesh filename="package://RRR_Cater/RX1/rx1_description/meshes/caster_wheel.obj" scale="0.657895 0.657895 0.657895" />
      </geometry>
      <material name="black">
        <color rgba="0.1 0.1 0.1 1.0" />
      </material>
    </visual>
    <collision>
      <origin rpy="1.57057 0.0 0" xyz="0 0 0" />
      <geometry>
        <cylinder length="0.025" radius="0.05" />
      </geometry>
      <surface>
        <contact>
          <collide_bitmask value="0xFFFF" />
        </contact>
        <friction>
          <ode>
            <mu value="1.0" />
            <mu2 value="1.0" />
            <slip1 value="0.0" />
            <slip2 value="0.0" />
          </ode>
        </friction>
      </surface>
    </collision>
  </link>
  <joint name="caster_rear_right_axle_joint" type="continuous">
    <origin rpy="0 0 0" xyz="0.02510000 0.00000000 -0.0020659999999999984" />
    <axis xyz="0 1 0" />
    <parent link="caster_rear_right_pivot_link" />
    <child link="caster_rear_right_wheel_link" />
    <dynamics damping="0.001" friction="0.0" />
  </joint>
  <link name="lidar_link">
    <inertial>
      <mass value="0.5" />
      <inertia ixx="0.001" ixy="0.0" ixz="0.0" iyy="0.001" iyz="0.0" izz="0.001" />
    </inertial>
    <visual>
      <origin rpy="0 0 0" xyz="0 0 0" />
      <geometry>
        <mesh filename="package://RRR_Cater/RX1/rx1_description/meshes/lidar.obj" scale="0.001 0.001 0.001" />
      </geometry>
      <material name="lidar_material">
        <color rgba="0.2 0.2 0.2 1.0" />
      </material>
    </visual>
    <collision>
      <origin rpy="0 0 0" xyz="0 0 0" />
      <geometry>
        <mesh filename="package://RRR_Cater/RX1/rx1_description/meshes/lidar.obj" scale="0.001 0.001 0.001" />
      </geometry>
    </collision>
  </link>
  <joint name="lidar_joint" type="fixed">
    <origin rpy="0 0 0" xyz="0 0 1.267" />
    <parent link="cater_platform_link" />
    <child link="lidar_link" />
  </joint>
  <link name="cater_left_wheel_link">
    <inertial>
      <mass value="3.0" />
      <inertia ixx="0.063680" ixy="0.0" ixz="0.0" iyy="0.121410" iyz="0.0" izz="0.063680" />
    </inertial>
    <visual>
      <origin rpy="1.57057 -1.57057 0" xyz="0 0 0" />
      <geometry>
        <mesh filename="package://RRR_Cater/RX1/rx1_description/meshes/carter_wheel.obj" scale="0.423333 0.423333 0.423333" />
      </geometry>
      <material name="black">
        <color rgba="0.1 0.1 0.1 1.0" />
      </material>
    </visual>
    <collision>
      <origin rpy="1.57057 -1.57057 0" xyz="0 -0.05 0" />
      <geometry>
        <cylinder length="0.1" radius="0.1016" />
      </geometry>
      <surface>
        <friction>
          <ode>
            <mu value="20.0" />
            <mu2 value="20.0" />
            <slip1 value="0.0" />
            <slip2 value="0.0" />
          </ode>
        </friction>
      </surface>
    </collision>
  </link>
  <joint name="cater_left_wheel_joint" type="continuous">
    <origin rpy="0 0 0" xyz="0.057437 0.31420517 -0.519651" />
    <axis xyz="0 1 0" />
    <parent link="cater_platform_link" />
    <child link="cater_left_wheel_link" />
  <dynamics damping="0.1" friction="0.0" /></joint>
  <link name="cater_right_wheel_link">
    <inertial>
      <mass value="3.0" />
      <inertia ixx="0.063680" ixy="0.0" ixz="0.0" iyy="0.121410" iyz="0.0" izz="0.063680" />
    </inertial>
    <visual>
      <origin rpy="-1.57057 -1.57057 0" xyz="0 0 0" />
      <geometry>
        <mesh filename="package://RRR_Cater/RX1/rx1_description/meshes/carter_wheel.obj" scale="0.423333 0.423333 0.423333" />
      </geometry>
      <material name="black">
        <color rgba="0.1 0.1 0.1 1.0" />
      </material>
    </visual>
    <collision>
      <origin rpy="-1.57057 -1.57057 0" xyz="0 0.05 0" />
      <geometry>
        <cylinder length="0.1" radius="0.1016" />
      </geometry>
      <surface>
        <friction>
          <ode>
            <mu value="20.0" />
            <mu2 value="20.0" />
            <slip1 value="0.0" />
            <slip2 value="0.0" />
          </ode>
        </friction>
      </surface>
    </collision>
  </link>
  <joint name="cater_right_wheel_joint" type="continuous">
    <origin rpy="0 0 0" xyz="0.057437 -0.31420517 -0.519651" />
    <axis xyz="0 1 0" />
    <parent link="cater_platform_link" />
    <child link="cater_right_wheel_link" />
  <dynamics damping="0.1" friction="0.0" /></joint>
</robot>